Workbook

Sheet 00_README
A1: EXCEL ADVANCED TOPICS — PRACTICE WORKBOOK
A2: Facilities Management edition · built for Senior Project Coordinator interview prep at Rapport
A4: HOW TO USE
A5: 1. Work through the sheets IN ORDER (00 → 20). Each one builds on the previous.
A6: 2. Every topic sheet has three zones: LEARN (concepts), PRACTICE (try it yourself), CHALLENGE (harder).
A7: 3. The yellow-tinted cells are where YOU write formulas. The green-tinted cells are worked solutions.
A8: 4. The data tables (Stores, Assets, Providers, Employees, Tickets) are your sandbox — experiment freely.
A9: 5. Power Query & Power BI are GUI-driven — those sheets are written as step-by-step walkthroughs.
A10: 6. Before the interview: attempt sheet 20_Interview_Qs from memory. Answers in 99_Solutions.
A12: ROADMAP
B13: Sheet | C13: What it covers
B14: 00_README | C14: You are here
B15: 01_Foundations | C15: Zero-knowledge primer: cells, references, 10 core formulas
B16: 02_Stores | C16: 30 Rapport stores
B17: 03_Assets | C17: ~190 assets across those stores
B18: 04_Providers | C18: 8 service providers
B19: 05_Employees | C19: 12 FM team members
B20: 06_Tickets | C20: 220 maintenance tickets — the main analysis dataset
B21: 07_MessyData | C21: Deliberately unclean ticket export — used in Power Query
B22: 10_PivotTables | C22: Summarise tickets by region, priority, provider, month
B23: 11_VLOOKUP_XLOOKUP | C23: Join tickets to stores / providers / assets — the #1 analyst skill
B24: 12_Dashboards | C24: Build a one-page FM KPI dashboard
... B28: 99_Solutions | C28: Worked answers — review AFTER you attempt
A30: RECOMMENDED 7-DAY PLAN
B31: Day | C31: Focus
B32: Day 1 | C32: Read 01_Foundations. Explore Stores / Assets / Tickets — sort, filter, autofill.
B33: Day 2 | C33: Work through 10_PivotTables. Build 5 different pivot views of the tickets.
B34: Day 3 | C34: Work through 11_VLOOKUP_XLOOKUP. Join tickets to stores and providers.
B35: Day 4 | C35: Build 12_Dashboards — 4 KPI cards + 2 charts.
B36: Day 5 | C36: Follow 13_PowerQuery — import messy data, clean it, load the result.
B37: Day 6 | C37: Read 14_PowerBI twice. If possible, install Power BI Desktop (free) and try it.
B38: Day 7 | C38: Answer 20_Interview_Qs from memory. Re-do anything that felt shaky.
A41: TIP · Open this in Excel DESKTOP (not just Excel for Web). Power Query, advanced pivots, and refreshable queries are desktop-only features.
A43: WHY THIS MATTERS AT RAPPORT · Every exercise mirrors a real task from the Senior Project Coordinator job ad: maintaining trackers, reporting on service providers, verifying assets across stores, producing structured reports. When you interview, you can reference this workbook as a portfolio piece.

Sheet 01_Foundations
A1: 01 · FOUNDATIONS — the absolute basics
A2: If you already know cells, references, and basic formulas, skim this and jump to sheet 10.
A4: CELLS & REFERENCES
A5: • A cell is the intersection of a column (letter) and a row (number). B3 = column B, row 3.
A6: • A formula starts with = . Example: in B3, =A1+A2 adds A1 and A2 and shows the result.
A7: • Relative reference (A1): changes when you copy the formula down/across.
A8: • Absolute reference ($A$1): stays fixed. Press F4 (Windows) while editing to toggle $.
A9: • Mixed reference ($A1 or A$1): one part locked, the other relative.
A10: • Range: A1:A10 means A1 through A10. Ranges are what you feed into SUM, AVERAGE, etc.
A12: TEN CORE FORMULAS — memorise these
B13: Function | C13: Example | D13: What it does
B14: SUM | C14: =SUM(B2:B20) -> 0 | D14: Adds all values
B15: AVERAGE | C15: =AVERAGE(B2:B20) | D15: Arithmetic mean
B16: COUNT | C16: =COUNT(B2:B20) -> 0 | D16: Counts numeric cells
B17: COUNTA | C17: =COUNTA(B2:B20) -> 8 | D17: Counts any non-empty cells
B18: COUNTIF | C18: =COUNTIF(C2:C20,"Closed") -> 0 | D18: Counts cells meeting a condition
B19: SUMIF | C19: =SUMIF(C2:C20,"Closed",D2:D20) -> 0 | D19: Sum D where C is 'Closed'
B20: SUMIFS | C20: =SUMIFS(D2:D20,C2:C20,"Closed",B2:B20,"High") -> 0 | D20: Sum with multiple conditions
B21: IF | C21: =IF(A1>100,"Over","Under") -> Over | D21: One-of-two logic
B22: IFS | C22: =ifs(A1>90,"A",A1>80,"B",A1>70,"C",TRUE(),"F") | D22: Multi-branch IF (modern)
B23: TEXT | C23: =TEXT(TODAY(),"dd-mmm-yyyy") -> 24-Apr-2026 | D23: Format numbers/dates as text
A25: TRY IT — write the formula in the yellow cells
A26: Sample numbers are in column H. Answers in 99_Solutions.
B27: # | C27: Task | D27: Your formula (write here) | H27: Num | I27: Status
B28: 1 | C28: Sum of H2:H8 (the numbers column) | H28: 10 | I28: Open
B29: 2 | C29: Count how many "Closed" in I2:I8 | H29: 20 | I29: Closed
B30: 3 | C30: Average of H2:H8 | H30: 30 | I30: Closed
B31: 4 | C31: IF the sum is greater than 500, return 'Big', else 'Small' | H31: 150 | I31: In Progress
B32: 5 | C32: The current date, formatted as DD-MMM-YYYY | H32: 75 | I32: Closed
H33: 200 | I33: Open
A34: KEYBOARD SHORTCUTS (learn these — they save hours)
B35: Shortcut | C35: What it does
B36: Ctrl + C / Ctrl + V | C36: Copy / Paste
B37: Ctrl + Z / Ctrl + Y | C37: Undo / Redo
B38: Ctrl + Arrow | C38: Jump to edge of data
B39: Ctrl + Shift + Arrow | C39: Select from here to edge
B40: Ctrl + T | C40: Turn a range into an Excel Table (do this always)
B41: Ctrl + Shift + L | C41: Toggle filters
B42: F4 (while editing) | C42: Toggle absolute / relative reference
B43: Alt + = | C43: Auto-sum
...

Sheet 02_Stores
A1: 02 · STORES (reference table, 30 rows)
A2: StoreID | B2: StoreName | C2: Region | D2: City | E2: Format | F2: SqFt | G2: OpenDate | H2: FM_Manager_ID
A3: ST1001 | B3: Rapport Glasgow Shopping Centre | C3: Scotland | D3: Glasgow | E3: Shopping Centre | F3: 15884 | G3: 39206 | H3: EMP108
A4: ST1002 | B4: Rapport Cambridge Outlet | C4: East | D4: Cambridge | E4: Outlet | F4: 12675 | G4: 42829 | H4: EMP108
A5: ST1003 | B5: Rapport London Outlet | C5: South | D5: London | E5: Outlet | F5: 9090 | G5: 38701 | H5: EMP105
A6: ST1004 | B6: Rapport Reading High Street | C6: South | D6: Reading | E6: High Street | F6: 11685 | G6: 39600 | H6: EMP101
A7: ST1005 | B7: Rapport London Shopping Centre | C7: South | D7: London | E7: Shopping Centre | F7: 2150 | G7: 43046 | H7: EMP107
A8: ST1006 | B8: Rapport Reading Flagship | C8: South | D8: Reading | E8: Flagship | F8: 10644 | G8: 41137 | H8: EMP109
A9: ST1007 | B9: Rapport Sheffield Retail Park | C9: North | D9: Sheffield | E9: Retail Park | F9: 5782 | G9: 41131 | H9: EMP101
A10: ST1008 | B10: Rapport Oxford Shopping Centre | C10: South | D10: Oxford | E10: Shopping Centre | F10: 17109 | G10: 39528 | H10: EMP112
A11: ST1009 | B11: Rapport Cardiff Flagship | C11: West | D11: Cardiff | E11: Flagship | F11: 14175 | G11: 42361 | H11: EMP109
A12: ST1010 | B12: Rapport Oxford Shopping Centre | C12: South | D12: Oxford | E12: Shopping Centre | F12: 15599 | G12: 40673 | H12: EMP110
A13: ST1011 | B13: Rapport Norwich Shopping Centre | C13: East | D13: Norwich | E13: Shopping Centre | F13: 8444 | G13: 44942 | H13: EMP104
A14: ST1012 | B14: Rapport Reading Outlet | C14: South | D14: Reading | E14: Outlet | F14: 8788 | G14: 40347 | H14: EMP112
... A32: ST1030 | B32: Rapport Edinburgh Flagship | C32: Scotland | D32: Edinburgh | E32: Flagship | F32: 6152 | G32: 44306 | H32: EMP107

Sheet 03_Assets
A1: 03 · ASSETS (one row per physical asset)
A2: AssetID | B2: StoreID | C2: Category | D2: AssetType | E2: InstallDate | F2: WarrantyEnd | G2: Status | H2: Cost_GBP
A3: AS5001 | B3: ST1001 | C3: Plumbing | D3: Water Heater | E3: 45123 | F3: 45854 | G3: Active | H3: 320
A4: AS5002 | B4: ST1001 | C4: IT Equipment | D4: Back Office PC | E4: 43838 | F4: 45665 | G4: Active | H4: 1800
A5: AS5003 | B5: ST1001 | C5: Refrigeration | D5: Chiller Cabinet | E5: 43922 | F5: 45748 | G5: Active | H5: 1800
A6: AS5004 | B6: ST1001 | C6: Security | D6: CCTV Camera | E6: 43972 | F6: 45798 | G6: Decommissioned | H6: 2500
A7: AS5005 | B7: ST1001 | C7: Lighting | D7: Display Spotlight | E7: 44148 | F7: 45974 | G7: Active | H7: 1200
A8: AS5006 | B8: ST1002 | C8: Plumbing | D8: Water Heater | E8: 45562 | F8: 46657 | G8: Active | H8: 1800
A9: AS5007 | B9: ST1002 | C9: Plumbing | D9: WC Cistern | E9: 43660 | F9: 45487 | G9: Active | H9: 5200
A10: AS5008 | B10: ST1002 | C10: Refrigeration | D10: Chiller Cabinet | E10: 43978 | F10: 44708 | G10: Active | H10: 5200
A11: AS5009 | B11: ST1002 | C11: Plumbing | D11: WC Cistern | E11: 44881 | F11: 46707 | G11: Active | H11: 1200
A12: AS5010 | B12: ST1002 | C12: Lighting | D12: Emergency Light | E12: 43790 | F12: 44886 | G12: Active | H12: 2500
A13: AS5011 | B13: ST1002 | C13: IT Equipment | D13: Back Office PC | E13: 44733 | F13: 46559 | G13: Active | H13: 2500
A14: AS5012 | B14: ST1002 | C14: Lighting | D14: LED Panel | E14: 45025 | F14: 46852 | G14: Active | H14: 1200
... A204: AS5202 | B204: ST1030 | C204: Fire Safety | D204: Extinguisher | E204: 44578 | F204: 45308 | G204: Active | H204: 12000

Sheet 04_Providers
A1: 04 · SERVICE PROVIDERS (8 contractors)
A2: ProviderID | B2: ProviderName | C2: Service | D2: Rating | E2: AnnualContract_GBP | F2: ContractStart | G2: ContractEnd
A3: PRV201 | B3: Mercury Facilities Ltd | C3: HVAC | D3: 4.6 | E3: 185000 | F3: 45035 | G3: 45766
A4: PRV202 | B4: Brightwell Electrical | C4: Lighting | D4: 4.3 | E4: 142000 | F4: 45174 | G4: 45905
A5: PRV203 | B5: ColdChain Engineering | C5: Refrigeration | D5: 4.8 | E5: 210000 | F5: 45097 | G5: 45828
A6: PRV204 | B6: SecureGuard Systems | C6: Security | D6: 4.1 | E6: 95000 | F6: 45159 | G6: 45890
A7: PRV205 | B7: Thames Plumbing Services | C7: Plumbing | D7: 3.9 | E7: 68000 | F7: 45202 | G7: 45933
A8: PRV206 | B8: SafeSite Fire Protection | C8: Fire Safety | D8: 4.7 | E8: 120000 | F8: 45200 | G8: 45931
A9: PRV207 | B9: TechSupport Direct | C9: IT Equipment | D9: 4 | E9: 85000 | F9: 45147 | G9: 45878
A10: PRV208 | B10: FloorPro UK | C10: Flooring | D10: 4.2 | E10: 55000 | F10: 45177 | G10: 45908

Sheet 05_Employees
A1: 05 · EMPLOYEES (FM team)
A2: EmployeeID | B2: FullName | C2: Department | D2: Role | E2: HireDate | F2: AnnualSalary_GBP | G2: Email
A3: EMP101 | B3: Oliver Jones | C3: Facilities | D3: FM Manager | E3: 43914 | F3: 65000 | G3: oliver.jones@rapport.co.uk
A4: EMP102 | B4: Leo Wilson | C4: Procurement | D4: Procurement Lead | E4: 43375 | F4: 58000 | G4: leo.wilson@rapport.co.uk
A5: EMP103 | B5: Noah Thomas | C5: Projects | D5: Projects Lead | E5: 45095 | F5: 52000 | G5: noah.thomas@rapport.co.uk
A6: EMP104 | B6: Isla Smith | C6: Facilities | D6: FM Manager | E6: 44054 | F6: 52000 | G6: isla.smith@rapport.co.uk
A7: EMP105 | B7: Oscar Walker | C7: Operations | D7: Operations Lead | E7: 44993 | F7: 42000 | G7: oscar.walker@rapport.co.uk
A8: EMP106 | B8: Amelia Taylor | C8: Compliance | D8: Compliance Lead | E8: 42811 | F8: 58000 | G8: amelia.taylor@rapport.co.uk
A9: EMP107 | B9: Charlie Walker | C9: Procurement | D9: Procurement Lead | E9: 42973 | F9: 52000 | G9: charlie.walker@rapport.co.uk
A10: EMP108 | B10: Charlie White | C10: Procurement | D10: Procurement Lead | E10: 44010 | F10: 52000 | G10: charlie.white@rapport.co.uk
A11: EMP109 | B11: Noah White | C11: Projects | D11: Projects Lead | E11: 44882 | F11: 42000 | G11: noah.white@rapport.co.uk
A12: EMP110 | B12: Jack Wilson | C12: Projects | D12: Projects Lead | E12: 45196 | F12: 46000 | G12: jack.wilson@rapport.co.uk
A13: EMP111 | B13: Lily Roberts | C13: Compliance | D13: Compliance Lead | E13: 45644 | F13: 65000 | G13: lily.roberts@rapport.co.uk
A14: EMP112 | B14: Lily Roberts | C14: Operations | D14: Operations Lead | E14: 44192 | F14: 42000 | G14: lily.roberts@rapport.co.uk

Sheet 06_Tickets
A1: 06 · MAINTENANCE TICKETS (220 rows — your main analysis dataset)
A2: TicketID | B2: LogDate | C2: StoreID | D2: AssetID | E2: ProviderID | F2: IssueType | G2: Priority | H2: Status | I2: Cost_GBP | J2: ResolutionDays
A3: TK2025001 | B3: 46107 | C3: ST1025 | D3: AS5160 | E3: PRV206 | F3: Compliance Check | G3: Critical | H3: Closed | I3: 2600 | J3: 0
A4: TK2025002 | B4: 46034 | C4: ST1003 | D4: AS5014 | E4: PRV205 | F4: Inspection | G4: High | H4: In Progress | I4: 120
A5: TK2025003 | B5: 46046 | C5: ST1023 | D5: AS5147 | E5: PRV203 | F5: Routine Maintenance | G5: Medium | H5: In Progress | I5: 620
A6: TK2025004 | B6: 46073 | C6: ST1007 | D6: AS5041 | E6: PRV203 | F6: Upgrade | G6: Medium | H6: Open | I6: 85
A7: TK2025005 | B7: 46081 | C7: ST1009 | D7: AS5054 | E7: PRV201 | F7: Routine Maintenance | G7: Low | H7: Escalated | I7: 1200
A8: TK2025006 | B8: 46076 | C8: ST1026 | D8: AS5174 | E8: PRV208 | F8: Routine Maintenance | G8: Critical | H8: Closed | I8: 180 | J8: 1
A9: TK2025007 | B9: 46033 | C9: ST1007 | D9: AS5038 | E9: PRV207 | F9: Installation | G9: High | H9: Closed | I9: 480 | J9: 1
A10: TK2025008 | B10: 46087 | C10: ST1012 | D10: AS5079 | E10: PRV208 | F10: Inspection | G10: Medium | H10: In Progress | I10: 340
A11: TK2025009 | B11: 46113 | C11: ST1002 | D11: AS5006 | E11: PRV205 | F11: Upgrade | G11: High | H11: In Progress | I11: 1800
A12: TK2025010 | B12: 46045 | C12: ST1001 | D12: AS5003 | E12: PRV203 | F12: Routine Maintenance | G12: Medium | H12: Escalated | I12: 120
A13: TK2025011 | B13: 46124 | C13: ST1029 | D13: AS5194 | E13: PRV201 | F13: Upgrade | G13: Medium | H13: Closed | I13: 480 | J13: 3
A14: TK2025012 | B14: 46115 | C14: ST1012 | D14: AS5076 | E14: PRV204 | F14: Routine Maintenance | G14: Medium | H14: Closed | I14: 1200 | J14: 7
A15: TK2025013 | B15: 46091 | C15: ST1005 | D15: AS5024 | E15: PRV203 | F15: Routine Maintenance | G15: High | H15: Closed | I15: 85 | J15: 4
A16: TK2025014 | B16: 46030 | C16: ST1004 | D16: AS5021 | E16: PRV204 | F16: Compliance Check | G16: Medium | H16: Closed | I16: 2600 | J16: 8
A17: TK2025015 | B17: 46108 | C17: ST1002 | D17: AS5009 | E17: PRV205 | F17: Routine Maintenance | G17: Low | H17: Closed | I17: 620 | J17: 5
A18: TK2025016 | B18: 46050 | C18: ST1015 | D18: AS5096 | E18: PRV207 | F18: Inspection | G18: Low | H18: Awaiting Parts | I18: 1800
A19: TK2025017 | B19: 46135 | C19: ST1008 | D19: AS5044 | E19: PRV206 | F19: Compliance Check | G19: Medium | H19: In Progress | I19: 850
A20: TK2025018 | B20: 46035 | C20: ST1016 | D20: AS5104 | E20: PRV201 | F20: Upgrade | G20: Critical | H20: Closed | I20: 850 | J20: 0
A21: TK2025019 | B21: 46048 | C21: ST1011 | D21: AS5070 | E21: PRV205 | F21: Installation | G21: High | H21: Closed | I21: 2600 | J21: 5
A22: TK2025020 | B22: 46106 | C22: ST1012 | D22: AS5072 | E22: PRV208 | F22: Compliance Check | G22: High | H22: Escalated | I22: 480
A23: TK2025021 | B23: 46038 | C23: ST1025 | D23: AS5167 | E23: PRV204 | F23: Upgrade | G23: High | H23: In Progress | I23: 340
A24: TK2025022 | B24: 46093 | C24: ST1018 | D24: AS5119 | E24: PRV204 | F24: Installation | G24: Medium | H24: Closed | I24: 850 | J24: 7
A25: TK2025023 | B25: 46070 | C25: ST1014 | D25: AS5094 | E25: PRV206 | F25: Routine Maintenance | G25: Low | H25: In Progress | I25: 850
A26: TK2025024 | B26: 46118 | C26: ST1012 | D26: AS5073 | E26: PRV204 | F26: Upgrade | G26: High | H26: Closed | I26: 1200 | J26: 3
A27: TK2025025 | B27: 46029 | C27: ST1030 | D27: AS5199 | E27: PRV201 | F27: Routine Maintenance | G27: Medium | H27: Closed | I27: 2600 | J27: 5
A28: TK2025026 | B28: 46120 | C28: ST1028 | D28: AS5184 | E28: PRV207 | F28: Routine Maintenance | G28: Low | H28: Open | I28: 480
A29: TK2025027 | B29: 46071 | C29: ST1008 | D29: AS5047 | E29: PRV204 | F29: Breakdown | G29: Medium | H29: In Progress | I29: 2600
A30: TK2025028 | B30: 46061 | C30: ST1024 | D30: AS5157 | E30: PRV204 | F30: Compliance Check | G30: Critical | H30: Open | I30: 620
A31: TK2025029 | B31: 46045 | C31: ST1012 | D31: AS5072 | E31: PRV208 | F31: Upgrade | G31: Medium | H31: Open | I31: 1800
A32: TK2025030 | B32: 46099 | C32: ST1012 | D32: AS5078 | E32: PRV205 | F32: Upgrade | G32: Medium | H32: Closed | I32: 1800 | J32: 4
A33: TK2025031 | B33: 46117 | C33: ST1025 | D33: AS5165 | E33: PRV201 | F33: Routine Maintenance | G33: Medium | H33: Closed | I33: 480 | J33: 4
A34: TK2025032 | B34: 46116 | C34: ST1026 | D34: AS5170 | E34: PRV203 | F34: Installation | G34: Medium | H34: Closed | I34: 620 | J34: 7
A35: TK2025033 | B35: 46069 | C35: ST1017 | D35: AS5110 | E35: PRV202 | F35: Installation | G35: Medium | H35: Closed | I35: 340 | J35: 4
A36: TK2025034 | B36: 46121 | C36: ST1029 | D36: AS5190 | E36: PRV207 | F36: Inspection | G36: Low | H36: Closed | I36: 850 | J36: 7
A37: TK2025035 | B37: 46120 | C37: ST1002 | D37: AS5007 | E37: PRV205 | F37: Installation | G37: Low | H37: Open | I37: 620
A38: TK2025036 | B38: 46089 | C38: ST1001 | D38: AS5004 | E38: PRV204 | F38: Inspection | G38: High | H38: In Progress | I38: 340
A39: TK2025037 | B39: 46097 | C39: ST1007 | D39: AS5040 | E39: PRV203 | F39: Upgrade | G39: Critical | H39: Closed | I39: 340 | J39: 0
A40: TK2025038 | B40: 46105 | C40: ST1012 | D40: AS5073 | E40: PRV204 | F40: Upgrade | G40: Low | H40: In Progress | I40: 2600
...

Sheet 07_MessyData
A1: 07 · MESSY DATA — a realistic raw export with 7 problems
A2: This is how data actually arrives from outside systems. Your Power Query exercise: turn it into a clean table.
A4: Scan the table below. You should spot SEVEN distinct data-quality issues. List them in the yellow cells, then sheet 13_PowerQuery shows you how to fix each one.
A6: THE SEVEN PROBLEMS (fill in as you find them)
B7: Problem 1:
B8: Problem 2:
B9: Problem 3:
B10: Problem 4:
B11: Problem 5:
B12: Problem 6:
B13: Problem 7:
A15: RAW EXPORT (messy)
B17: Ticket Ref | C17: Log Date | D17: store | E17: ISSUE | F17: priority | G17: Cost (£) | H17: Status | I17: Provider Name
B18: TK2025001 | C18: 15/01/2026 | D18: ST1003 | E18: Breakdown | F18: High | G18: £250 | H18: Closed | I18: Mercury Facilities Ltd
B19: TK2025002 | C19: 16-01-2026 | D19: ST1007 | E19: Routine Maintenance | F19: medium | G19: 180 | H19: closed | I19: ColdChain Engineering
B20: TK2025003 | C20: 2026-01-17 | D20: ST1012 | E20: Inspection | F20: Low | G20: £120 | H20: Open | I20: SafeSite Fire Protection
B21: TK2025004 | C21: 17/1/2026 | D21: ST1003 | E21: breakdown | F21: HIGH | G21: £250 | H21: CLOSED | I21: Mercury Facilities
B22: TK2025005 | D22: ST1005 | E22: Installation | F22: Medium | G22: 620 | H22: In Progress | I22: Brightwell Electrical
B23: TK2025006 | C23: 20/01/2026 | D23: ST1008 | E23: Upgrade | F23: critical | G23: £1,800 | H23: Escalated | I23: SecureGuard Systems
B24: TK2025007 | C24: 21/01/2026 | D24: ST1002 | E24: Routine Maintenance | F24: Low | G24: £85 | I24: Thames Plumbing Services
B25: TK2025008 | C25: 23/01/2026 | D25: ST1015 | E25: Compliance Check | F25: Medium | G25: £340 | H25: Closed | I25: SafeSite Fire Protection
B26: TK2025009 | C26: 24/1/2026 | D26: ST1003 | E26: Breakdown | F26: High | G26: 250 | H26: closed | I26: Mercury Facilities Ltd
B27: TK2025010 | C27: 25/01/2026 | D27: ST1011 | E27: Breakdown | F27: Medium | G27: £480 | H27: In Progress | I27: Brightwell Electrical
B28: TK2025002 | C28: 16-01-2026 | D28: ST1007 | E28: Routine Maintenance | F28: medium | G28: 180 | H28: closed | I28: ColdChain Engineering
B29: TK2025011 | C29: 27/01/2026 | D29: ST1019 | E29: Inspection | F29: Low | G29: £120 | H29: Closed | I29: SafeSite Fire Protection

Sheet 10_PivotTables
A1: 10 · PIVOT TABLES — the fastest way to summarise data
A2: A Pivot Table answers questions like 'total cost by region' or 'tickets by priority and month' WITHOUT writing any formulas. Master this first.
A4: LEARN · What is a Pivot Table?
A5: • A Pivot Table is a drag-and-drop summary tool. You pick a field for Rows, a field for Columns, and a field for Values — Excel groups the data for you.
A6: • You build it from a RANGE or a TABLE. Always convert your data to a Table first (Ctrl + T) — pivots will then grow as the table grows.
A7: • Four drop zones: Filters (top), Columns (across), Rows (down), Values (the numbers). Drag fields between them to change the view.
A8: • Aggregations you can use on Values: Sum, Count, Average, Min, Max, Product, StdDev — click the 'i' next to the field to change it.
A10: HOW TO INSERT A PIVOT TABLE (Excel Desktop)
A11: 1. Click anywhere inside the ticket data on sheet '06_Tickets'.
A12: 2. Press Ctrl + T to convert it to an Excel Table (tick 'My table has headers'). Name it 'tblTickets' in Table Design ribbon.
A13: 3. Go to Insert ribbon → PivotTable → From Table/Range → New Worksheet.
A14: 4. The PivotTable Fields pane appears on the right. You see every column from the table.
... A19: PRACTICE — five pivot views to build
B20: # | C20: Build this view | D20: Hint
B21: P1 | C21: Total Cost_GBP by Status. | D21: Drop Status into Rows, Cost_GBP into Values.
B22: P2 | C22: Count of tickets by Priority. | D22: Drop Priority into Rows, TicketID into Values → change to Count.
B23: P3 | C23: Sum of Cost_GBP by Priority AND Status. | D23: Priority in Rows, Status in Columns, Cost_GBP in Values.
B24: P4 | C24: Average ResolutionDays by Priority. | D24: Priority in Rows, ResolutionDays in Values → change aggregation to Average.
B25: P5 | C25: Cost by month. | D25: Right-click any LogDate in the pivot → Group → Months. Then drop into Rows with Cost in Values.
A27: FORMULA-EQUIVALENT VIEW (if you can't use Pivots)
A28: These SUMIFS / COUNTIFS formulas produce the SAME numbers as pivots. Useful when your file is shared with someone who can't refresh pivots, or when you're building a live dashboard.
B29: Priority | C29: Count of tickets | D29: Total cost (£) | E29: Avg cost (£)
B30: Low | C30: =COUNTIF('06_Tickets'!G3:G222,"Low") -> 67 | D30: =SUMIFS('06_Tickets'!I3:I222,'06_Tickets'!G3:G222,"Low") -> 53660 | E30: =AVERAGEIFS('06_Tickets'!I3:I222,'06_Tickets'!G3:G222,"Low") -> 800.89552
B31: Medium | C31: =COUNTIF('06_Tickets'!G3:G222,"Medium") -> 84 | D31: =SUMIFS('06_Tickets'!I3:I222,'06_Tickets'!G3:G222,"Medium") -> 74870 | E31: =AVERAGEIFS('06_Tickets'!I3:I222,'06_Tickets'!G3:G222,"Medium") -> 891.30952
B32: High | C32: =COUNTIF('06_Tickets'!G3:G222,"High") -> 45 | D32: =SUMIFS('06_Tickets'!I3:I222,'06_Tickets'!G3:G222,"High") -> 37030 | E32: =AVERAGEIFS('06_Tickets'!I3:I222,'06_Tickets'!G3:G222,"High") -> 822.88889
B33: Critical | C33: =COUNTIF('06_Tickets'!G3:G222,"Critical") -> 24 | D33: =SUMIFS('06_Tickets'!I3:I222,'06_Tickets'!G3:G222,"Critical") -> 18520 | E33: =AVERAGEIFS('06_Tickets'!I3:I222,'06_Tickets'!G3:G222,"Critical") -> 771.66667
B34: TOTAL | C34: =COUNTA('06_Tickets'!A3:A222) -> 220 | D34: =SUM('06_Tickets'!I3:I222) -> 184080 | E34: =AVERAGE('06_Tickets'!I3:I222) -> 836.72727
A36: CHALLENGE
A37: 1. Build a pivot showing the TOP 5 most expensive StoreIDs by total Cost_GBP. (Right-click → Filter → Top 10 → change to 5).
A38: 2. Add a Slicer on Priority. A Slicer is a clickable filter next to the pivot. Pivot Table Analyze ribbon → Insert Slicer.
A39: 3. Show 'percentage of total cost' instead of raw cost. Right-click the value field → Show Values As → % of Column Total.

Sheet 11_VLOOKUP_XLOOKUP
A1: 11 · VLOOKUP & XLOOKUP — joining data across tables
A2: Your ticket table has StoreID but not StoreName. Your lookup job: pull the matching StoreName from the Stores table.
A4: LEARN · VLOOKUP syntax
A5: =VLOOKUP( what_to_find , where_to_search , which_column_to_return , exact_match? )
A6: Rules to remember: • The column you're searching on (first column of the range) MUST be the left-most column. • The 4th argument should almost always be FALSE (exact match). TRUE is only for sorted numeric lookups. • If the value isn't found, VLOOKUP returns an 'N/A' error — wrap it in IFERROR to show a friendly message.
A8: LEARN · XLOOKUP (modern replacement, Excel 365/2021+)
A9: =xlookup( what_to_find , lookup_array , return_array , [if_not_found] )
A10: Why XLOOKUP beats VLOOKUP: • Lookup column can be ANYWHERE — not forced to the left. • Built-in 'if not found' argument — no need for IFERROR. • Defaults to exact match (safer). • Works left-to-right OR right-to-left. • Can return an entire row with one formula.
A12: PRACTICE — enrich the ticket table
A13: Below is a mini copy of the first 12 tickets. Write the lookup formula for each yellow cell. Use VLOOKUP for the first 2, XLOOKUP for the rest. Solutions on sheet 99_Solutions.
B15: TicketID | C15: StoreID | D15: ProviderID | E15: StoreName (VLOOKUP) | F15: Region (VLOOKUP) | G15: ProviderName (XLOOKUP) | H15: Service (XLOOKUP) | I15: Contract £ (XLOOKUP)
B16: TK2025001 | C16: ST1003 | D16: PRV201
B17: TK2025002 | C17: ST1007 | D17: PRV203
B18: TK2025003 | C18: ST1012 | D18: PRV206
B19: TK2025004 | C19: ST1003 | D19: PRV201
B20: TK2025005 | C20: ST1005 | D20: PRV202
B21: TK2025006 | C21: ST1008 | D21: PRV204
B22: TK2025007 | C22: ST1002 | D22: PRV205
B23: TK2025008 | C23: ST1015 | D23: PRV206
B24: TK2025009 | C24: ST1003 | D24: PRV201
B25: TK2025010 | C25: ST1011 | D25: PRV202
A27: Hints (target for column 5 — StoreName using VLOOKUP): =VLOOKUP(C16, '02_Stores'!$A$3:$H$32, 2, FALSE) For column 7 — ProviderName using XLOOKUP: =XLOOKUP(D16, '04_Providers'!$A$3:$A$10, '04_Providers'!$B$3:$B$10, "Not Found")
A29: LIVE WORKED EXAMPLE (already filled in — learn by reading)
B30: TicketID | C30: StoreID | D30: ProviderID | E30: StoreName | F30: Region | G30: ProviderName | H30: Service | I30: Contract £
B31: TK2025001 | C31: ST1003 | D31: PRV201 | E31: =VLOOKUP(C31,'02_Stores'!$A$3:$H$32,2,FALSE()) -> Rapport London Outlet | F31: =VLOOKUP(C31,'02_Stores'!$A$3:$H$32,3,FALSE()) -> South | G31: =IFERROR(INDEX('04_Providers'!$B$3:$B$10,MATCH(D31,'04_Providers'!$A$3:$A$10,0)),"-") -> Mercury Facilities Ltd | H31: =IFERROR(INDEX('04_Providers'!$C$3:$C$10,MATCH(D31,'04_Providers'!$A$3:$A$10,0)),"-") -> HVAC | I31: =IFERROR(INDEX('04_Providers'!$E$3:$E$10,MATCH(D31,'04_Providers'!$A$3:$A$10,0)),0) -> 185000
B32: TK2025002 | C32: ST1007 | D32: PRV203 | E32: =VLOOKUP(C32,'02_Stores'!$A$3:$H$32,2,FALSE()) -> Rapport Sheffield Retail Park | F32: =VLOOKUP(C32,'02_Stores'!$A$3:$H$32,3,FALSE()) -> North | G32: =IFERROR(INDEX('04_Providers'!$B$3:$B$10,MATCH(D32,'04_Providers'!$A$3:$A$10,0)),"-") -> ColdChain Engineering | H32: =IFERROR(INDEX('04_Providers'!$C$3:$C$10,MATCH(D32,'04_Providers'!$A$3:$A$10,0)),"-") -> Refrigeration | I32: =IFERROR(INDEX('04_Providers'!$E$3:$E$10,MATCH(D32,'04_Providers'!$A$3:$A$10,0)),0) -> 210000
B33: TK2025003 | C33: ST1012 | D33: PRV206 | E33: =VLOOKUP(C33,'02_Stores'!$A$3:$H$32,2,FALSE()) -> Rapport Reading Outlet | F33: =VLOOKUP(C33,'02_Stores'!$A$3:$H$32,3,FALSE()) -> South | G33: =IFERROR(INDEX('04_Providers'!$B$3:$B$10,MATCH(D33,'04_Providers'!$A$3:$A$10,0)),"-") -> SafeSite Fire Protection | H33: =IFERROR(INDEX('04_Providers'!$C$3:$C$10,MATCH(D33,'04_Providers'!$A$3:$A$10,0)),"-") -> Fire Safety | I33: =IFERROR(INDEX('04_Providers'!$E$3:$E$10,MATCH(D33,'04_Providers'!$A$3:$A$10,0)),0) -> 120000
B34: TK2025004 | C34: ST1003 | D34: PRV201 | E34: =VLOOKUP(C34,'02_Stores'!$A$3:$H$32,2,FALSE()) -> Rapport London Outlet | F34: =VLOOKUP(C34,'02_Stores'!$A$3:$H$32,3,FALSE()) -> South | G34: =IFERROR(INDEX('04_Providers'!$B$3:$B$10,MATCH(D34,'04_Providers'!$A$3:$A$10,0)),"-") -> Mercury Facilities Ltd | H34: =IFERROR(INDEX('04_Providers'!$C$3:$C$10,MATCH(D34,'04_Providers'!$A$3:$A$10,0)),"-") -> HVAC | I34: =IFERROR(INDEX('04_Providers'!$E$3:$E$10,MATCH(D34,'04_Providers'!$A$3:$A$10,0)),0) -> 185000
B35: TK2025005 | C35: ST1005 | D35: PRV202 | E35: =VLOOKUP(C35,'02_Stores'!$A$3:$H$32,2,FALSE()) -> Rapport London Shopping Centre | F35: =VLOOKUP(C35,'02_Stores'!$A$3:$H$32,3,FALSE()) -> South | G35: =IFERROR(INDEX('04_Providers'!$B$3:$B$10,MATCH(D35,'04_Providers'!$A$3:$A$10,0)),"-") -> Brightwell Electrical | H35: =IFERROR(INDEX('04_Providers'!$C$3:$C$10,MATCH(D35,'04_Providers'!$A$3:$A$10,0)),"-") -> Lighting | I35: =IFERROR(INDEX('04_Providers'!$E$3:$E$10,MATCH(D35,'04_Providers'!$A$3:$A$10,0)),0) -> 142000
A37: CHALLENGE
A38: 1. Two-way lookup — given a StoreID and a Priority, return the TOTAL cost. (Hint: SUMIFS is usually cleaner than nested lookups).
A39: 2. Reverse lookup — given a StoreName, return the StoreID. VLOOKUP can't do this (lookup column isn't leftmost). XLOOKUP CAN. Write both and see.
A40: 3. 'IFERROR wrap' — rewrite your VLOOKUP so that a missing ID returns "Not on file" instead of the lookup-error value.

Sheet 12_Dashboards
A1: 12 · DASHBOARDS — build a one-page FM report
A2: A dashboard = KPIs (headline numbers) + charts + a filter strip, all on one screen. Here we build a live one.
A4: KPI CARDS (these update if you change ticket data)
B6: TOTAL TICKETS | E6: OPEN / IN PROGRESS | H6: CLOSED | K6: TOTAL COST (£)
B7: =COUNTA('06_Tickets'!A3:A222) -> 220 | E7: =COUNTIFS('06_Tickets'!H3:H222,"Open")+COUNTIFS('06_Tickets'!H3:H222,"In Progress") -> 87 | H7: =COUNTIF('06_Tickets'!H3:H222,"Closed") -> 103 | K7: =SUM('06_Tickets'!I3:I222) -> 184080
B10: AVG COST / TICKET | E10: AVG RESOLUTION DAYS | H10: % CRITICAL | K10: HIGHEST SINGLE COST
B11: =AVERAGE('06_Tickets'!I3:I222) -> 836.72727 | E11: =AVERAGE('06_Tickets'!J3:J222) -> 5.5048544 | H11: =COUNTIF('06_Tickets'!G3:G222,"Critical")/COUNTA('06_Tickets'!A3:A222) -> 0.10909091 | K11: =MAX('06_Tickets'!I3:I222) -> 2600
A15: SUMMARY TABLES (chart data — keep visible)
B17: Priority | C17: Tickets | D17: Cost (£) | F17: Status | G17: Tickets | H17: Cost (£) | J17: Month | K17: Tickets | L17: Cost (£)
B18: Low | C18: =COUNTIF('06_Tickets'!G3:G222,"Low") -> 67 | D18: =SUMIFS('06_Tickets'!I3:I222,'06_Tickets'!G3:G222,"Low") -> 53660 | F18: Open | G18: =COUNTIF('06_Tickets'!H3:H222,"Open") -> 36 | H18: =SUMIFS('06_Tickets'!I3:I222,'06_Tickets'!H3:H222,"Open") -> 32510 | J18: Jan 2026 | K18: =SUMPRODUCT((MONTH('06_Tickets'!B3:B222)=1)*1) -> 68 | L18: =SUMPRODUCT((MONTH('06_Tickets'!B3:B222)=1)*'06_Tickets'!I3:I222) -> 58245
B19: Medium | C19: =COUNTIF('06_Tickets'!G3:G222,"Medium") -> 84 | D19: =SUMIFS('06_Tickets'!I3:I222,'06_Tickets'!G3:G222,"Medium") -> 74870 | F19: In Progress | G19: =COUNTIF('06_Tickets'!H3:H222,"In Progress") -> 51 | H19: =SUMIFS('06_Tickets'!I3:I222,'06_Tickets'!H3:H222,"In Progress") -> 43025 | J19: Feb 2026 | K19: =SUMPRODUCT((MONTH('06_Tickets'!B3:B222)=2)*1) -> 43 | L19: =SUMPRODUCT((MONTH('06_Tickets'!B3:B222)=2)*'06_Tickets'!I3:I222) -> 36640
B20: High | C20: =COUNTIF('06_Tickets'!G3:G222,"High") -> 45 | D20: =SUMIFS('06_Tickets'!I3:I222,'06_Tickets'!G3:G222,"High") -> 37030 | F20: Awaiting Parts | G20: =COUNTIF('06_Tickets'!H3:H222,"Awaiting Parts") -> 21 | H20: =SUMIFS('06_Tickets'!I3:I222,'06_Tickets'!H3:H222,"Awaiting Parts") -> 18120 | J20: Mar 2026 | K20: =SUMPRODUCT((MONTH('06_Tickets'!B3:B222)=3)*1) -> 49 | L20: =SUMPRODUCT((MONTH('06_Tickets'!B3:B222)=3)*'06_Tickets'!I3:I222) -> 41800
B21: Critical | C21: =COUNTIF('06_Tickets'!G3:G222,"Critical") -> 24 | D21: =SUMIFS('06_Tickets'!I3:I222,'06_Tickets'!G3:G222,"Critical") -> 18520 | F21: Closed | G21: =COUNTIF('06_Tickets'!H3:H222,"Closed") -> 103 | H21: =SUMIFS('06_Tickets'!I3:I222,'06_Tickets'!H3:H222,"Closed") -> 86535 | J21: Apr 2026 | K21: =SUMPRODUCT((MONTH('06_Tickets'!B3:B222)=4)*1) -> 60 | L21: =SUMPRODUCT((MONTH('06_Tickets'!B3:B222)=4)*'06_Tickets'!I3:I222) -> 47395
F22: Escalated | G22: =COUNTIF('06_Tickets'!H3:H222,"Escalated") -> 9 | H22: =SUMIFS('06_Tickets'!I3:I222,'06_Tickets'!H3:H222,"Escalated") -> 3890
A59: HOW THIS DASHBOARD WORKS
A60: • Every KPI card is a live formula — change any ticket cost on sheet 06 and the card updates.
A61: • The three summary tables are the 'engine room' that feeds the charts. Keep them visible so you can see what's being charted.
A62: • Charts are linked to the summary tables, not the raw data. This is the most maintainable pattern.
A63: • To add a SLICER: click any pivot → Insert → Slicer → pick field. Slicers can connect to multiple pivots (right-click → Report Connections).
A64: • TO MAKE IT A POLISHED REPORT: View → Uncheck Gridlines & Headings, zoom to 90%, freeze the KPI row.
A66: PRACTICE
A67: 1. Add a 9th KPI: 'Critical tickets still open' — count tickets where Priority='Critical' AND Status<>'Closed'.
A68: 2. Add a bar chart showing total cost by Region. (Hint: you'll need VLOOKUP to get Region from StoreID first, or a helper column on sheet 06.)
A69: 3. Add conditional formatting to the Priority table: colour-scale green→red on the 'Cost (£)' column.
A70: 4. Protect the sheet (Review → Protect Sheet) so your KPIs can't be overwritten.

Sheet 13_PowerQuery
A1: 13 · POWER QUERY — clean, reshape, automate
A2: Power Query is Excel's built-in ETL tool. Use it whenever you need to clean or combine data from outside sources — instead of doing it by hand every month, you record the steps once and click Refresh.
A4: WHAT IS POWER QUERY & WHY YOU'LL USE IT AT RAPPORT
A5: • Your ticket / asset / provider exports arrive in different formats every month. Doing 'find-and-replace' by hand is slow and error-prone.
A6: • Power Query lets you IMPORT a file, RECORD the cleaning steps, and then REFRESH the query next time — same steps run automatically.
A7: • It lives under the 'Data' ribbon: Data → Get Data → From File / From Folder / From Table or Range.
A8: • All your steps appear in a pane called 'Applied Steps' — you can edit, reorder or delete them any time.
A9: • Power Query uses a language called M behind the scenes, but you rarely touch it — the ribbon does 90% of the work.
A11: EXERCISE — clean sheet '07_MessyData' step by step
A12: Open sheet 07_MessyData (if you haven't already). You saw 7 problems. Here's how Power Query fixes each.
B14: Step | C14: What to do
B15: STEP 1 · Load into Power Query | C15: Click anywhere inside the messy table on sheet 07_MessyData. Data ribbon → Get Data → From Other Sources → From Table/Range. Excel will ask you to convert to a Table first if it isn't one — click OK.
B16: STEP 2 · Promote headers (if needed) | C16: If the first row isn't treated as headers, click Home → Use First Row as Headers.
B17: STEP 3 · Rename columns to clean names | C17: Double-click each column header and rename: 'Ticket Ref' → 'TicketID', 'Log Date' → 'LogDate', 'store' → 'StoreID', 'ISSUE' → 'IssueType', 'priority' → 'Priority', 'Cost (£)' → 'Cost_GBP', 'Status' → 'Status', 'Provider Name' → 'Provider'.
B18: STEP 4 · Trim & Clean text columns | C18: Select columns StoreID, IssueType, Priority, Provider → Transform → Format → Trim. Then Format → Clean (removes non-printing characters).
B19: STEP 5 · Standardise text case | C19: Select Priority and Status → Transform → Format → Capitalize Each Word. Now 'critical', 'HIGH', 'Critical' all become 'Critical'.
B20: STEP 6 · Fix mixed date formats | C20: Select LogDate → Transform → Data Type → Using Locale → Date → English (United Kingdom). This parses '15/01/2026', '16-01-2026' and '2026-01-17' all into real dates.
B21: STEP 7 · Fix the Cost column | C21: Cost has '£250' and '250' mixed. Select Cost_GBP → Transform → Replace Values → '£' with nothing. Then Transform → Data Type → Decimal Number.
B22: STEP 8 · Fix blank rows | C22: Home → Remove Rows → Remove Blank Rows. Also filter the Status column drop-down to un-tick '(null)' if you want to exclude rows with no status, or keep them for investigation.
B23: STEP 9 · Remove duplicates | C23: Home → Remove Rows → Remove Duplicates. (Select ALL columns first or just the key column TicketID.)
B24: STEP 10 · Standardise provider names | C24: Select Provider → Replace Values → 'Mercury Facilities' with 'Mercury Facilities Ltd'. Repeat for any other typos you found.
B25: STEP 11 · Close & Load | C25: Home → Close & Load To → Table → Existing Worksheet. Pick a cell on a new sheet. You now have a clean table that can be REFRESHED next month: right-click the green table → Refresh.
A27: KEY POWER QUERY MOVES TO REMEMBER
B28: Move | C28: Why it matters for FM reporting
B29: Merge Queries | C29: Join two tables (like VLOOKUP but for entire tables). Home → Merge Queries. Perfect for joining tickets to stores.
B30: Append Queries | C30: Stack two tables on top of each other (like UNION in SQL). Perfect for combining monthly exports.
B31: Unpivot Columns | C31: Turn a wide month-by-column layout (Jan, Feb, Mar...) into a tall one (Month, Value). Transform → Unpivot Columns.
B32: Group By | C32: Aggregate: 'Total cost per Region'. Transform → Group By.
B33: From Folder | C33: Point at a folder — Power Query reads EVERY file in it and stacks them. Game-changer for monthly data.
B34: Refresh All | C34: Data → Refresh All (Ctrl + Alt + F5). Re-runs all your queries with the latest source data.

Sheet 14_PowerBI
A1: 14 · POWER BI — from Excel to interactive dashboards
A2: Power BI Desktop is a free app from Microsoft that takes your Excel data and lets you build interactive dashboards and publish them to the web. If you know pivots & Power Query, you already know 80% of Power BI.
A4: WHAT IT IS
A5: • Power BI Desktop = a free Windows app. Download from: https://aka.ms/pbidesktop
A6: • Power BI Service = the web portal at app.powerbi.com where you publish your reports.
A7: • You build REPORTS (visuals on pages), which sit inside a DATASET, which draws from SOURCES (Excel, SQL, SharePoint, etc.).
A8: • Refresh: in Desktop, click Home → Refresh. In the Service, you schedule automatic refreshes.
A10: WALKTHROUGH — publish this workbook as a Power BI report
B11: Step | C11: Action
B12: 1 · Install Power BI Desktop | C12: Go to https://aka.ms/pbidesktop (free). Windows only. Sign in with your Microsoft account.
B13: 2 · Get the data | C13: Home ribbon → Get Data → Excel Workbook → navigate to THIS file. Tick '06_Tickets', '02_Stores', '04_Providers', '03_Assets'. Click Load.
B14: 3 · Build relationships (like a database) | C14: Go to Model view (left sidebar, third icon). Drag StoreID from Tickets onto StoreID in Stores. Drag ProviderID from Tickets onto ProviderID in Providers. Drag AssetID similarly. Now your tables are joined.
B15: 4 · Your first visual — Cost by Region | C15: Report view. Drag Region (from Stores) onto the canvas. Drag Cost_GBP (from Tickets) on top of it. Power BI auto-builds a bar chart. Change the chart type via the Visualizations pane.
B16: 5 · Add a KPI card | C16: Click the 'Card' visual. Drag Cost_GBP into it. You get a headline number. Repeat for Ticket count, Avg resolution days.
B17: 6 · Add filters | C17: Drag Priority into the Filters pane at the right. Your whole report can now be filtered by priority with one click.
B18: 7 · Add a SLICER (clickable filter) | C18: Slicer visual → drag Region in. Click a region button → every visual updates instantly.
B19: 8 · Publish to the web | C19: Home → Publish → My Workspace. Power BI uploads it to app.powerbi.com. You get a share link.
B20: 9 · Schedule refresh | C20: In the Service, go to Datasets → Settings → Scheduled refresh → pick time & frequency. Your Excel source must be on OneDrive/SharePoint for this to work automatically.
A22: WHAT POWER BI DOES THAT EXCEL CAN'T (EASILY)
A23: • Works with MUCH larger data (millions of rows). Excel tops out around 1M rows per sheet.
A24: • Interactivity is built in — click one visual and everything else filters.
A25: • Publishes online so colleagues can view on phone / browser without Excel.
A26: • DAX — a formula language that extends beyond what Excel pivots can do (time-intelligence, rolling averages, YoY comparisons).
A27: • Role-based security — restrict who sees which stores / regions.
A29: DAX — the ONE formula to learn first
A30: CALCULATE is Power BI's SUMIFS. Syntax: CALCULATE( expression, filter1, filter2, ... )
A31: Example · Total cost of CLOSED tickets: Closed Cost = CALCULATE( SUM(Tickets[Cost_GBP]), Tickets[Status] = "Closed" ) This becomes a reusable "measure" that you can drag onto any visual.
A33: NO POWER BI DESKTOP? YOU CAN STILL LEARN
A34: • Read Microsoft's free Power BI Guided Learning: https://learn.microsoft.com/power-bi/ • Watch 'SQLBI' and 'Guy in a Cube' on YouTube — industry standards. • If you're on a Mac, install Power BI Desktop in a Windows VM or use Power BI Service web-based report building (limited).

Sheet 20_Interview_Qs
A1: 20 · INTERVIEW QUESTIONS — data analyst / project coordinator Excel
A2: Answer each question out loud before checking 99_Solutions. For a Senior Project Coordinator role at Rapport, interviewers usually ask a mix of definitions (Q1–5), scenario judgement (Q6–10) and applied demos (Q11–15).
B4: # | C4: Question | D4: Your answer (or notes)
B5: 1 | C5: What is the difference between VLOOKUP and XLOOKUP?
B6: 2 | C6: When would you use SUMIFS instead of a Pivot Table?
B7: 3 | C7: What does $ do in a cell reference?
B8: 4 | C8: Name three things Power Query can do that formulas can't.
B9: 5 | C9: What is a Slicer and why use one?
B10: 6 | C10: You receive a monthly ticket export from a service provider. How would you process it?
B11: 7 | C11: A VLOOKUP returns a lookup-error value for 50 of 200 rows. What are the first three things you check?
B12: 8 | C12: How would you show 'top 5 providers by total cost'?
B13: 9 | C13: Describe how you'd build a weekly KPI report that refreshes automatically.
B14: 10 | C14: The FM Manager wants to see 'open critical tickets older than 7 days' on the front page. How?
B15: 11 | C15: What's the difference between a table (Ctrl+T) and a plain range?
B16: 12 | C16: Walk me through INDEX/MATCH.
... B19: 15 | C19: How do you make a report 'audit-ready'?

Sheet 99_Solutions
A1: 99 · SOLUTIONS — check AFTER you try
A2: This sheet has complete answers for every PRACTICE and CHALLENGE in the workbook, plus the interview Qs.
A4: 01_Foundations — practice answers
B5: # | C5: Task | D5: Answer
B6: 1 | C6: Sum of H2:H8 | D6: =SUM(H2:H8) -> 0
B7: 2 | C7: Count 'Closed' in I2:I8 | D7: =COUNTIF(I2:I8,"Closed") -> 0
B8: 3 | C8: Average of H2:H8 | D8: =AVERAGE(H2:H8)
B9: 4 | C9: IF sum > 500 → 'Big' else 'Small' | D9: =IF(SUM(H2:H8)>500,"Big","Small") -> Small
B10: 5 | C10: Today's date as dd-mmm-yyyy | D10: =TEXT(TODAY(),"dd-mmm-yyyy") -> 24-Apr-2026
A12: 11_VLOOKUP_XLOOKUP — practice answers
B13: Col | C13: Field | D13: Formula
B14: 1 | C14: StoreName (VLOOKUP) | D14: =VLOOKUP(c{row},'02_Stores'!$A$3:$H$32,2,FALSE())
B15: 2 | C15: Region (VLOOKUP) | D15: =VLOOKUP(c{row},'02_Stores'!$A$3:$H$32,3,FALSE())
B16: 3 | C16: ProviderName (XLOOKUP) | D16: =xlookup(d{row},'04_Providers'!$A$3:$A$10,'04_Providers'!$B$3:$B$10,"Not Found")
B17: 4 | C17: Service (XLOOKUP) | D17: =xlookup(d{row},'04_Providers'!$A$3:$A$10,'04_Providers'!$C$3:$C$10,"Not Found")
B18: 5 | C18: Contract £ (XLOOKUP) | D18: =xlookup(d{row},'04_Providers'!$A$3:$A$10,'04_Providers'!$E$3:$E$10,0)
A20: CHALLENGE 1 (two-way lookup): =SUMIFS('06_Tickets'!$I$3:$I$222, '06_Tickets'!$C$3:$C$222, StoreID, '06_Tickets'!$G$3:$G$222, Priority)
A21: CHALLENGE 2 (reverse lookup): XLOOKUP works directly: =XLOOKUP("Rapport London Flagship", '02_Stores'!$B$3:$B$32, '02_Stores'!$A$3:$A$32) With VLOOKUP you would need to rearrange the source columns.
A22: CHALLENGE 3 (IFERROR wrap): =IFERROR(VLOOKUP(C4,'02_Stores'!$A$3:$H$32,2,FALSE), "Not on file")
A24: 07_MessyData — the seven problems
B25: # | C25: Problem | D25: Fix
B26: 1 | C26: Mixed date formats (DD/MM/YYYY, DD-MM-YYYY, YYYY-MM-DD) | D26: Power Query 'Using Locale → UK Date'.
B27: 2 | C27: Leading/trailing whitespace in StoreID (' ST1007', 'ST1008 ') | D27: Transform → Trim.
B28: 3 | C28: Inconsistent casing in Priority & Status ('closed', 'CLOSED', 'Closed') | D28: Capitalize Each Word.
B29: 4 | C29: Cost column mixes '£250' text and '250' numbers | D29: Replace Values → remove '£', then Data Type → Decimal.
B30: 5 | C30: Duplicate row (TK2025002 appears twice) | D30: Remove Duplicates.
B31: 6 | C31: Blank cells (LogDate missing on row 5, Status missing on row 7) | D31: Remove Blank Rows OR Fill Down.
B32: 7 | C32: Provider name typo ('Mercury Facilities' vs 'Mercury Facilities Ltd') | D32: Replace Values.
A34: 20_Interview_Qs — model answers
B35: # | C35: Question | D35: Model answer
B36: 1 | C36: What is the difference between VLOOKUP and XLOOKUP? | D36: XLOOKUP works in any direction, returns 'if not found' built-in, defaults to exact match. VLOOKUP only looks right and needs 4 args.
B37: 2 | C37: When would you use SUMIFS instead of a Pivot Table? | D37: When the destination cell needs to be in a specific layout (e.g. a management report where cells are in fixed positions), or when sharing with someone who won't refresh the pivot.
B38: 3 | C38: What does $ do in a cell reference? | D38: Locks that part of the reference when copying. $A$1 stays fixed; A1 changes relative to the new position.
B39: 4 | C39: Name three things Power Query can do that formulas can't. | D39: Handle millions of rows, import from folders/web/SharePoint, persist cleaning steps that re-run on refresh.
B40: 5 | C40: What is a Slicer and why use one? | D40: A visual filter button set. Click to filter one or many pivots / charts simultaneously — much faster than filter drop-downs for users.
B41: 6 | C41: You receive a monthly ticket export from a service provider. How would you process it? | D41: Save to a watched folder → Power Query 'From Folder' → merges all past exports → cleans columns → loads to a table → connects to a dashboard. Next month, just drop the new file in and Refresh.
B42: 7 | C42: A VLOOKUP returns a lookup-error value for 50 of 200 rows. What are the first three things you check? | D42: 1) Leading/trailing spaces in the lookup key (use TRIM), 2) text vs number mismatch (format both as text), 3) lookup column is actually the leftmost column of the range.
B43: 8 | C43: How would you show 'top 5 providers by total cost'? | D43: Pivot of Provider × Cost → sort descending → right-click → Filter → Top 10 → change 10 to 5.
B44: 9 | C44: Describe how you'd build a weekly KPI report that refreshes automatically. | D44: Data imported with Power Query (from a shared folder or SQL), Pivot Tables built on the query, dashboard sheet with KPI formulas linked to those pivots, Refresh All bound to a keyboard shortcut or macro. If Power BI is available, schedule refresh on publish.
B45: 10 | C45: The FM Manager wants to see 'open critical tickets older than 7 days' on the front page. How? | D45: Helper column on the ticket table: =IF(AND(Priority="Critical",Status<>"Closed",TODAY()-LogDate>7),1,0). Then a KPI card or filtered table using that flag. Could also do with a dynamic array FILTER function.
...
